{
  "id": "bridge",
  "name": "Ponte do riacho",
  "version": 1,
  "blocks": [
    {
      "x": 0,
      "y": 0,
      "z": 0,
      "type": "sand"
    },
    {
      "x": 0,
      "y": 0,
      "z": 1,
      "type": "water"
    },
    {
      "x": 0,
      "y": 0,
      "z": 2,
      "type": "water"
    },
    {
      "x": 0,
      "y": 0,
      "z": 3,
      "type": "water"
    },
    {
      "x": 0,
      "y": 0,
      "z": 4,
      "type": "sand"
    },
    {
      "x": 1,
      "y": 0,
      "z": 0,
      "type": "sand"
    },
    {
      "x": 1,
      "y": 0,
      "z": 1,
      "type": "water"
    },
    {
      "x": 1,
      "y": 0,
      "z": 2,
      "type": "water"
    },
    {
      "x": 1,
      "y": 0,
      "z": 3,
      "type": "water"
    },
    {
      "x": 1,
      "y": 0,
      "z": 4,
      "type": "sand"
    },
    {
      "x": 2,
      "y": 0,
      "z": 0,
      "type": "sand"
    },
    {
      "x": 2,
      "y": 0,
      "z": 1,
      "type": "water"
    },
    {
      "x": 2,
      "y": 0,
      "z": 2,
      "type": "water"
    },
    {
      "x": 2,
      "y": 0,
      "z": 3,
      "type": "water"
    },
    {
      "x": 2,
      "y": 0,
      "z": 4,
      "type": "sand"
    },
    {
      "x": 3,
      "y": 0,
      "z": 0,
      "type": "sand"
    },
    {
      "x": 3,
      "y": 0,
      "z": 1,
      "type": "water"
    },
    {
      "x": 3,
      "y": 0,
      "z": 2,
      "type": "water"
    },
    {
      "x": 3,
      "y": 0,
      "z": 3,
      "type": "water"
    },
    {
      "x": 3,
      "y": 0,
      "z": 4,
      "type": "sand"
    },
    {
      "x": 4,
      "y": 0,
      "z": 0,
      "type": "sand"
    },
    {
      "x": 4,
      "y": 0,
      "z": 1,
      "type": "water"
    },
    {
      "x": 4,
      "y": 0,
      "z": 2,
      "type": "water"
    },
    {
      "x": 4,
      "y": 0,
      "z": 3,
      "type": "water"
    },
    {
      "x": 4,
      "y": 0,
      "z": 4,
      "type": "sand"
    },
    {
      "x": 0,
      "y": 1,
      "z": 1,
      "type": "oak_planks"
    },
    {
      "x": 0,
      "y": 1,
      "z": 2,
      "type": "oak_planks"
    },
    {
      "x": 0,
      "y": 1,
      "z": 3,
      "type": "oak_planks"
    },
    {
      "x": 1,
      "y": 1,
      "z": 1,
      "type": "oak_planks"
    },
    {
      "x": 1,
      "y": 1,
      "z": 2,
      "type": "oak_planks"
    },
    {
      "x": 1,
      "y": 1,
      "z": 3,
      "type": "oak_planks"
    },
    {
      "x": 2,
      "y": 1,
      "z": 1,
      "type": "oak_planks"
    },
    {
      "x": 2,
      "y": 1,
      "z": 2,
      "type": "oak_planks"
    },
    {
      "x": 2,
      "y": 1,
      "z": 3,
      "type": "oak_planks"
    },
    {
      "x": 3,
      "y": 1,
      "z": 1,
      "type": "oak_planks"
    },
    {
      "x": 3,
      "y": 1,
      "z": 2,
      "type": "oak_planks"
    },
    {
      "x": 3,
      "y": 1,
      "z": 3,
      "type": "oak_planks"
    },
    {
      "x": 4,
      "y": 1,
      "z": 1,
      "type": "oak_planks"
    },
    {
      "x": 4,
      "y": 1,
      "z": 2,
      "type": "oak_planks"
    },
    {
      "x": 4,
      "y": 1,
      "z": 3,
      "type": "oak_planks"
    },
    {
      "x": 0,
      "y": 2,
      "z": 1,
      "type": "wood"
    },
    {
      "x": 0,
      "y": 2,
      "z": 3,
      "type": "wood"
    },
    {
      "x": 1,
      "y": 2,
      "z": 1,
      "type": "wood"
    },
    {
      "x": 1,
      "y": 2,
      "z": 3,
      "type": "wood"
    },
    {
      "x": 2,
      "y": 2,
      "z": 1,
      "type": "wood"
    },
    {
      "x": 2,
      "y": 2,
      "z": 3,
      "type": "wood"
    },
    {
      "x": 3,
      "y": 2,
      "z": 1,
      "type": "wood"
    },
    {
      "x": 3,
      "y": 2,
      "z": 3,
      "type": "wood"
    },
    {
      "x": 4,
      "y": 2,
      "z": 1,
      "type": "wood"
    },
    {
      "x": 4,
      "y": 2,
      "z": 3,
      "type": "wood"
    },
    {
      "x": -1,
      "y": 0,
      "z": 2,
      "type": "sand"
    },
    {
      "x": 5,
      "y": 0,
      "z": 2,
      "type": "sand"
    }
  ]
}
