{
  "id": "house",
  "name": "Casa do bosque",
  "version": 1,
  "blocks": [
    {
      "x": 0,
      "y": 0,
      "z": 0,
      "type": "cobblestone"
    },
    {
      "x": 0,
      "y": 0,
      "z": 1,
      "type": "cobblestone"
    },
    {
      "x": 0,
      "y": 0,
      "z": 2,
      "type": "cobblestone"
    },
    {
      "x": 0,
      "y": 0,
      "z": 3,
      "type": "cobblestone"
    },
    {
      "x": 0,
      "y": 0,
      "z": 4,
      "type": "cobblestone"
    },
    {
      "x": 1,
      "y": 0,
      "z": 0,
      "type": "cobblestone"
    },
    {
      "x": 1,
      "y": 0,
      "z": 1,
      "type": "cobblestone"
    },
    {
      "x": 1,
      "y": 0,
      "z": 2,
      "type": "cobblestone"
    },
    {
      "x": 1,
      "y": 0,
      "z": 3,
      "type": "cobblestone"
    },
    {
      "x": 1,
      "y": 0,
      "z": 4,
      "type": "cobblestone"
    },
    {
      "x": 2,
      "y": 0,
      "z": 0,
      "type": "cobblestone"
    },
    {
      "x": 2,
      "y": 0,
      "z": 1,
      "type": "cobblestone"
    },
    {
      "x": 2,
      "y": 0,
      "z": 2,
      "type": "cobblestone"
    },
    {
      "x": 2,
      "y": 0,
      "z": 3,
      "type": "cobblestone"
    },
    {
      "x": 2,
      "y": 0,
      "z": 4,
      "type": "cobblestone"
    },
    {
      "x": 3,
      "y": 0,
      "z": 0,
      "type": "cobblestone"
    },
    {
      "x": 3,
      "y": 0,
      "z": 1,
      "type": "cobblestone"
    },
    {
      "x": 3,
      "y": 0,
      "z": 2,
      "type": "cobblestone"
    },
    {
      "x": 3,
      "y": 0,
      "z": 3,
      "type": "cobblestone"
    },
    {
      "x": 3,
      "y": 0,
      "z": 4,
      "type": "cobblestone"
    },
    {
      "x": 4,
      "y": 0,
      "z": 0,
      "type": "cobblestone"
    },
    {
      "x": 4,
      "y": 0,
      "z": 1,
      "type": "cobblestone"
    },
    {
      "x": 4,
      "y": 0,
      "z": 2,
      "type": "cobblestone"
    },
    {
      "x": 4,
      "y": 0,
      "z": 3,
      "type": "cobblestone"
    },
    {
      "x": 4,
      "y": 0,
      "z": 4,
      "type": "cobblestone"
    },
    {
      "x": 0,
      "y": 1,
      "z": 0,
      "type": "oak_planks"
    },
    {
      "x": 0,
      "y": 1,
      "z": 1,
      "type": "oak_planks"
    },
    {
      "x": 0,
      "y": 1,
      "z": 2,
      "type": "oak_planks"
    },
    {
      "x": 0,
      "y": 1,
      "z": 3,
      "type": "oak_planks"
    },
    {
      "x": 0,
      "y": 1,
      "z": 4,
      "type": "oak_planks"
    },
    {
      "x": 1,
      "y": 1,
      "z": 0,
      "type": "oak_planks"
    },
    {
      "x": 1,
      "y": 1,
      "z": 4,
      "type": "oak_planks"
    },
    {
      "x": 2,
      "y": 1,
      "z": 0,
      "type": "oak_planks"
    },
    {
      "x": 3,
      "y": 1,
      "z": 0,
      "type": "oak_planks"
    },
    {
      "x": 3,
      "y": 1,
      "z": 4,
      "type": "oak_planks"
    },
    {
      "x": 4,
      "y": 1,
      "z": 0,
      "type": "oak_planks"
    },
    {
      "x": 4,
      "y": 1,
      "z": 1,
      "type": "oak_planks"
    },
    {
      "x": 4,
      "y": 1,
      "z": 2,
      "type": "oak_planks"
    },
    {
      "x": 4,
      "y": 1,
      "z": 3,
      "type": "oak_planks"
    },
    {
      "x": 4,
      "y": 1,
      "z": 4,
      "type": "oak_planks"
    },
    {
      "x": 0,
      "y": 2,
      "z": 0,
      "type": "oak_planks"
    },
    {
      "x": 0,
      "y": 2,
      "z": 1,
      "type": "oak_planks"
    },
    {
      "x": 0,
      "y": 2,
      "z": 2,
      "type": "glass"
    },
    {
      "x": 0,
      "y": 2,
      "z": 3,
      "type": "oak_planks"
    },
    {
      "x": 0,
      "y": 2,
      "z": 4,
      "type": "oak_planks"
    },
    {
      "x": 1,
      "y": 2,
      "z": 0,
      "type": "oak_planks"
    },
    {
      "x": 1,
      "y": 2,
      "z": 4,
      "type": "oak_planks"
    },
    {
      "x": 2,
      "y": 2,
      "z": 0,
      "type": "glass"
    },
    {
      "x": 3,
      "y": 2,
      "z": 0,
      "type": "oak_planks"
    },
    {
      "x": 3,
      "y": 2,
      "z": 4,
      "type": "oak_planks"
    },
    {
      "x": 4,
      "y": 2,
      "z": 0,
      "type": "oak_planks"
    },
    {
      "x": 4,
      "y": 2,
      "z": 1,
      "type": "oak_planks"
    },
    {
      "x": 4,
      "y": 2,
      "z": 2,
      "type": "glass"
    },
    {
      "x": 4,
      "y": 2,
      "z": 3,
      "type": "oak_planks"
    },
    {
      "x": 4,
      "y": 2,
      "z": 4,
      "type": "oak_planks"
    },
    {
      "x": 0,
      "y": 3,
      "z": 0,
      "type": "oak_planks"
    },
    {
      "x": 0,
      "y": 3,
      "z": 1,
      "type": "oak_planks"
    },
    {
      "x": 0,
      "y": 3,
      "z": 2,
      "type": "oak_planks"
    },
    {
      "x": 0,
      "y": 3,
      "z": 3,
      "type": "oak_planks"
    },
    {
      "x": 0,
      "y": 3,
      "z": 4,
      "type": "oak_planks"
    },
    {
      "x": 1,
      "y": 3,
      "z": 0,
      "type": "oak_planks"
    },
    {
      "x": 1,
      "y": 3,
      "z": 4,
      "type": "oak_planks"
    },
    {
      "x": 2,
      "y": 3,
      "z": 0,
      "type": "oak_planks"
    },
    {
      "x": 2,
      "y": 3,
      "z": 4,
      "type": "oak_planks"
    },
    {
      "x": 3,
      "y": 3,
      "z": 0,
      "type": "oak_planks"
    },
    {
      "x": 3,
      "y": 3,
      "z": 4,
      "type": "oak_planks"
    },
    {
      "x": 4,
      "y": 3,
      "z": 0,
      "type": "oak_planks"
    },
    {
      "x": 4,
      "y": 3,
      "z": 1,
      "type": "oak_planks"
    },
    {
      "x": 4,
      "y": 3,
      "z": 2,
      "type": "oak_planks"
    },
    {
      "x": 4,
      "y": 3,
      "z": 3,
      "type": "oak_planks"
    },
    {
      "x": 4,
      "y": 3,
      "z": 4,
      "type": "oak_planks"
    },
    {
      "x": 0,
      "y": 4,
      "z": 0,
      "type": "brick"
    },
    {
      "x": 0,
      "y": 4,
      "z": 1,
      "type": "brick"
    },
    {
      "x": 0,
      "y": 4,
      "z": 2,
      "type": "brick"
    },
    {
      "x": 0,
      "y": 4,
      "z": 3,
      "type": "brick"
    },
    {
      "x": 0,
      "y": 4,
      "z": 4,
      "type": "brick"
    },
    {
      "x": 1,
      "y": 4,
      "z": 0,
      "type": "brick"
    },
    {
      "x": 1,
      "y": 4,
      "z": 1,
      "type": "brick"
    },
    {
      "x": 1,
      "y": 4,
      "z": 2,
      "type": "brick"
    },
    {
      "x": 1,
      "y": 4,
      "z": 3,
      "type": "brick"
    },
    {
      "x": 1,
      "y": 4,
      "z": 4,
      "type": "brick"
    },
    {
      "x": 2,
      "y": 4,
      "z": 0,
      "type": "brick"
    },
    {
      "x": 2,
      "y": 4,
      "z": 1,
      "type": "brick"
    },
    {
      "x": 2,
      "y": 4,
      "z": 2,
      "type": "brick"
    },
    {
      "x": 2,
      "y": 4,
      "z": 3,
      "type": "brick"
    },
    {
      "x": 2,
      "y": 4,
      "z": 4,
      "type": "brick"
    },
    {
      "x": 3,
      "y": 4,
      "z": 0,
      "type": "brick"
    },
    {
      "x": 3,
      "y": 4,
      "z": 1,
      "type": "brick"
    },
    {
      "x": 3,
      "y": 4,
      "z": 2,
      "type": "brick"
    },
    {
      "x": 3,
      "y": 4,
      "z": 3,
      "type": "brick"
    },
    {
      "x": 3,
      "y": 4,
      "z": 4,
      "type": "brick"
    },
    {
      "x": 4,
      "y": 4,
      "z": 0,
      "type": "brick"
    },
    {
      "x": 4,
      "y": 4,
      "z": 1,
      "type": "brick"
    },
    {
      "x": 4,
      "y": 4,
      "z": 2,
      "type": "brick"
    },
    {
      "x": 4,
      "y": 4,
      "z": 3,
      "type": "brick"
    },
    {
      "x": 4,
      "y": 4,
      "z": 4,
      "type": "brick"
    },
    {
      "x": 2,
      "y": 5,
      "z": 0,
      "type": "brick"
    },
    {
      "x": 2,
      "y": 5,
      "z": 1,
      "type": "brick"
    },
    {
      "x": 2,
      "y": 5,
      "z": 2,
      "type": "brick"
    },
    {
      "x": 2,
      "y": 5,
      "z": 3,
      "type": "brick"
    },
    {
      "x": 2,
      "y": 5,
      "z": 4,
      "type": "brick"
    }
  ]
}
