{
  "id": "monument",
  "name": "Farol da comunidade",
  "version": 1,
  "blocks": [
    {
      "x": 0,
      "y": 0,
      "z": 0,
      "type": "stone"
    },
    {
      "x": 0,
      "y": 0,
      "z": 1,
      "type": "stone"
    },
    {
      "x": 0,
      "y": 0,
      "z": 2,
      "type": "stone"
    },
    {
      "x": 0,
      "y": 0,
      "z": 3,
      "type": "stone"
    },
    {
      "x": 0,
      "y": 0,
      "z": 4,
      "type": "stone"
    },
    {
      "x": 1,
      "y": 0,
      "z": 0,
      "type": "stone"
    },
    {
      "x": 1,
      "y": 0,
      "z": 1,
      "type": "stone"
    },
    {
      "x": 1,
      "y": 0,
      "z": 2,
      "type": "stone"
    },
    {
      "x": 1,
      "y": 0,
      "z": 3,
      "type": "stone"
    },
    {
      "x": 1,
      "y": 0,
      "z": 4,
      "type": "stone"
    },
    {
      "x": 2,
      "y": 0,
      "z": 0,
      "type": "stone"
    },
    {
      "x": 2,
      "y": 0,
      "z": 1,
      "type": "stone"
    },
    {
      "x": 2,
      "y": 0,
      "z": 2,
      "type": "stone"
    },
    {
      "x": 2,
      "y": 0,
      "z": 3,
      "type": "stone"
    },
    {
      "x": 2,
      "y": 0,
      "z": 4,
      "type": "stone"
    },
    {
      "x": 3,
      "y": 0,
      "z": 0,
      "type": "stone"
    },
    {
      "x": 3,
      "y": 0,
      "z": 1,
      "type": "stone"
    },
    {
      "x": 3,
      "y": 0,
      "z": 2,
      "type": "stone"
    },
    {
      "x": 3,
      "y": 0,
      "z": 3,
      "type": "stone"
    },
    {
      "x": 3,
      "y": 0,
      "z": 4,
      "type": "stone"
    },
    {
      "x": 4,
      "y": 0,
      "z": 0,
      "type": "stone"
    },
    {
      "x": 4,
      "y": 0,
      "z": 1,
      "type": "stone"
    },
    {
      "x": 4,
      "y": 0,
      "z": 2,
      "type": "stone"
    },
    {
      "x": 4,
      "y": 0,
      "z": 3,
      "type": "stone"
    },
    {
      "x": 4,
      "y": 0,
      "z": 4,
      "type": "stone"
    },
    {
      "x": 1,
      "y": 1,
      "z": 1,
      "type": "brick"
    },
    {
      "x": 1,
      "y": 1,
      "z": 2,
      "type": "brick"
    },
    {
      "x": 1,
      "y": 1,
      "z": 3,
      "type": "brick"
    },
    {
      "x": 2,
      "y": 1,
      "z": 1,
      "type": "brick"
    },
    {
      "x": 2,
      "y": 1,
      "z": 2,
      "type": "brick"
    },
    {
      "x": 2,
      "y": 1,
      "z": 3,
      "type": "brick"
    },
    {
      "x": 3,
      "y": 1,
      "z": 1,
      "type": "brick"
    },
    {
      "x": 3,
      "y": 1,
      "z": 2,
      "type": "brick"
    },
    {
      "x": 3,
      "y": 1,
      "z": 3,
      "type": "brick"
    },
    {
      "x": 1,
      "y": 2,
      "z": 2,
      "type": "glass"
    },
    {
      "x": 2,
      "y": 2,
      "z": 1,
      "type": "glass"
    },
    {
      "x": 2,
      "y": 2,
      "z": 2,
      "type": "glass"
    },
    {
      "x": 2,
      "y": 2,
      "z": 3,
      "type": "glass"
    },
    {
      "x": 3,
      "y": 2,
      "z": 2,
      "type": "glass"
    },
    {
      "x": 2,
      "y": 3,
      "z": 2,
      "type": "cobblestone"
    },
    {
      "x": 2,
      "y": 4,
      "z": 2,
      "type": "sand"
    }
  ]
}
